<?xml version="1.0" ?>
<!-- This URDF was automatically created by SolidWorks to URDF Exporter! Originally created by Stephen Brawner (brawner@gmail.com) 
     Commit Version: 1.6.0-4-g7f85cfe  Build Version: 1.6.7995.38578
     For more information, please see http://wiki.ros.org/sw_urdf_exporter -->
<robot
  name="robot_name" xmlns:xacro="http://ros.org/wiki/xacro">

  <xacro:macro name="wheel_color">
    <visual>
    <material>
        <ambient>0.0 0.0 0.0 1</ambient>
        <diffuse>0.0 0.0 0.0 1</diffuse>
        <specular>0.1 0.1 0.1 1</specular>
        <emissive>0 0 0 0</emissive>
    </material>
    </visual>
  </xacro:macro>

  <link name="dummy_link"></link>
  <link
    name="base_link">
    <inertial>
      <origin
        xyz="-0.0073033 -0.023562 0.069997"
        rpy="0 0 0" />
      <mass
        value="5" />
      <inertia
        ixx="18.833"
        ixy="-1.0074E-15"
        ixz="-2.3889"
        iyy="41.12"
        iyz="-1.2296E-15"
        izz="42.702" />
    </inertial>
    <visual>
      <origin
        xyz="0 0 0"
        rpy="0 0 0" />
      <geometry>
        <mesh
          filename="package://busbot/meshes/base_link.STL" />
      </geometry>
      <material
        name="">
        <color
          rgba="0.79216 0.81961 0.93333 1" />
      </material>
    </visual>
    <collision>
      <origin
        xyz="0 0 0"
        rpy="0 0 0" />
      <geometry>
        <mesh
          filename="package://busbot/meshes/base_link.STL" />
      </geometry>
    </collision>
  </link>
  <joint name="dummy_joint" type="fixed">
    <origin rpy="0 0 0" xyz="0 0 0" />
    <parent link="dummy_link"/>
    <child link="base_link"/>
  </joint>
  <link
    name="fl_axle_link">
    <inertial>
      <origin
        xyz="0.014194 0 0.22795"
        rpy="0 0 0" />
      <mass
        value="4.0553" />
      <inertia
        ixx="0.059172"
        ixy="-8.8354E-19"
        ixz="-0.0066169"
        iyy="0.063463"
        iyz="-2.7904E-18"
        izz="0.009975" />
    </inertial>
    <visual>
      <origin
        xyz="0 0 0"
        rpy="0 0 0" />
      <geometry>
        <mesh
          filename="package://busbot/meshes/fl_axle_link.STL" />
      </geometry>
      <material
        name="">
        <color
          rgba="0.79216 0.81961 0.93333 1" />
      </material>
    </visual>
    <collision>
      <origin
        xyz="0 0 0"
        rpy="0 0 0" />
      <geometry>
        <mesh
          filename="package://busbot/meshes/fl_axle_link.STL" />
      </geometry>
    </collision>
  </link>
  <joint
    name="fl_axle_joint"
    type="revolute">
    <origin
      xyz="0.33385 0.15424 -0.035521"
      rpy="3.1416 0 1.5708" />
    <parent
      link="base_link" />
    <child
      link="fl_axle_link" />
    <axis
      xyz="0 0 1" />
    <limit
      lower="-3.14"
      upper="3.14"
      effort="100"
      velocity="1000" />
  </joint>
  <link
    name="fl_wheel_link">
    <inertial>
      <origin
        xyz="0 0 -0.065272"
        rpy="0 0 0" />
      <mass
        value="3" />
      <inertia
        ixx="0.065282"
        ixy="1.7347E-18"
        ixz="1.7758E-20"
        iyy="0.065282"
        iyz="1.0932E-20"
        izz="0.10708" />
    </inertial>
    <visual>
      <origin
        xyz="0 0 0"
        rpy="0 0 0" />
      <geometry>
        <mesh
          filename="package://busbot/meshes/fl_wheel_link.STL" />
      </geometry>
      <material
        name="">
        <color
          rgba="0.79608 0.82353 0.93725 1" />
      </material>
    </visual>
    <collision>
      <origin
        xyz="0 0 0"
        rpy="0 0 0" />
      <geometry>
        <mesh
          filename="package://busbot/meshes/fl_wheel_link.STL" />
      </geometry>
    </collision>
  </link>
  <joint
    name="fl_wheel_joint"
    type="continuous">
    <origin
      xyz="0.07874 0 0.3429"
      rpy="-1.5708 0.17044 1.5708" />
    <parent
      link="fl_axle_link" />
    <child
      link="fl_wheel_link" />
    <axis
      xyz="0 0 -1" />
    <limit
      effort="100"
      velocity="1000" />
  </joint>
  <link
    name="fr_axle_link">
    <inertial>
      <origin
        xyz="0.014194 -5.5511E-17 0.22795"
        rpy="0 0 0" />
      <mass
        value="4.0553" />
      <inertia
        ixx="0.059172"
        ixy="-2.3831E-18"
        ixz="-0.0066169"
        iyy="0.063463"
        iyz="1.6239E-18"
        izz="0.009975" />
    </inertial>
    <visual>
      <origin
        xyz="0 0 0"
        rpy="0 0 0" />
      <geometry>
        <mesh
          filename="package://busbot/meshes/fr_axle_link.STL" />
      </geometry>
      <material
        name="">
        <color
          rgba="0.79216 0.81961 0.93333 1" />
      </material>
    </visual>
    <collision>
      <origin
        xyz="0 0 0"
        rpy="0 0 0" />
      <geometry>
        <mesh
          filename="package://busbot/meshes/fr_axle_link.STL" />
      </geometry>
    </collision>
  </link>
  <joint
    name="fr_axle_joint"
    type="revolute">
    <origin
      xyz="0.33385 -0.20136 -0.035521"
      rpy="3.1416 0 -1.5708" />
    <parent
      link="base_link" />
    <child
      link="fr_axle_link" />
    <axis
      xyz="0 0 1" />
    <limit
      lower="-3.14"
      upper="3.14"
      effort="100"
      velocity="1000" />
  </joint>
  <link
    name="fr_wheel_link">
    <inertial>
      <origin
        xyz="5.5511E-17 -2.7756E-17 -0.065272"
        rpy="0 0 0" />
      <mass
        value="3" />
      <inertia
        ixx="0.065282"
        ixy="1.7347E-18"
        ixz="-2.4993E-18"
        iyy="0.065282"
        iyz="4.8336E-19"
        izz="0.10708" />
    </inertial>
    <visual>
      <origin
        xyz="0 0 0"
        rpy="0 0 0" />
      <geometry>
        <mesh
          filename="package://busbot/meshes/fr_wheel_link.STL" />
      </geometry>
      <material
        name="">
        <color
          rgba="0.79608 0.82353 0.93725 1" />
      </material>
    </visual>
    <collision>
      <origin
        xyz="0 0 0"
        rpy="0 0 0" />
      <geometry>
        <mesh
          filename="package://busbot/meshes/fr_wheel_link.STL" />
      </geometry>
    </collision>
  </link>
  <joint
    name="fr_wheel_joint"
    type="continuous">
    <origin
      xyz="0.07874 0 0.3429"
      rpy="1.5707963267949 -0.506662334036525 -1.5707963267949" />
    <parent
      link="fr_axle_link" />
    <child
      link="fr_wheel_link" />
    <axis
      xyz="0 0 -1" />
    <limit
      effort="100"
      velocity="1000" />
  </joint>
  <link
    name="bl_axle_link">
    <inertial>
      <origin
        xyz="0.014194 5.5511E-17 0.22795"
        rpy="0 0 0" />
      <mass
        value="4.0553" />
      <inertia
        ixx="0.059172"
        ixy="-1.0054E-18"
        ixz="-0.0066169"
        iyy="0.063463"
        iyz="-2.0351E-18"
        izz="0.009975" />
    </inertial>
    <visual>
      <origin
        xyz="0 0 0"
        rpy="0 0 0" />
      <geometry>
        <mesh
          filename="package://busbot/meshes/bl_axle_link.STL" />
      </geometry>
      <material
        name="">
        <color
          rgba="0.79216 0.81961 0.93333 1" />
      </material>
    </visual>
    <collision>
      <origin
        xyz="0 0 0"
        rpy="0 0 0" />
      <geometry>
        <mesh
          filename="package://busbot/meshes/bl_axle_link.STL" />
      </geometry>
    </collision>
  </link>
  <joint
    name="bl_axle_joint"
    type="fixed">
    <origin
      xyz="-0.42815 0.15424 -0.035521"
      rpy="3.1416 0 1.5708" />
    <parent
      link="base_link" />
    <child
      link="bl_axle_link" />
    <axis
      xyz="0 0 0" />
  </joint>
  <link
    name="bl_wheel_link">
    <inertial>
      <origin
        xyz="0 5.5511E-17 -0.065272"
        rpy="0 0 0" />
      <mass
        value="3" />
      <inertia
        ixx="0.065282"
        ixy="3.4694E-18"
        ixz="-2.174E-18"
        iyy="0.065282"
        iyz="-3.6224E-19"
        izz="0.10708" />
    </inertial>
    <visual>
      <origin
        xyz="0 0 0"
        rpy="0 0 0" />
      <geometry>
        <mesh
          filename="package://busbot/meshes/bl_wheel_link.STL" />
      </geometry>
      <material
        name="">
        <color
          rgba="0.79608 0.82353 0.93725 1" />
      </material>
    </visual>
    <collision>
      <origin
        xyz="0 0 0"
        rpy="0 0 0" />
      <geometry>
        <mesh
          filename="package://busbot/meshes/bl_wheel_link.STL" />
      </geometry>
    </collision>
  </link>
  <joint
    name="bl_wheel_joint"
    type="continuous">
    <origin
      xyz="0.0787399999999999 0 0.3429"
      rpy="-1.5707963267949 1.35941937592494 1.5707963267949" />
    <parent
      link="bl_axle_link" />
    <child
      link="bl_wheel_link" />
    <axis
      xyz="0 0 -1" />
    <limit
      effort="100"
      velocity="1000" />
  </joint>
  <link
    name="br_axle_link">
    <inertial>
      <origin
        xyz="0.014194 -5.5511E-17 0.22795"
        rpy="0 0 0" />
      <mass
        value="4.0553" />
      <inertia
        ixx="0.059172"
        ixy="-1.98E-18"
        ixz="-0.0066169"
        iyy="0.063463"
        iyz="-1.1155E-18"
        izz="0.009975" />
    </inertial>
    <visual>
      <origin
        xyz="0 0 0"
        rpy="0 0 0" />
      <geometry>
        <mesh
          filename="package://busbot/meshes/br_axle_link.STL" />
      </geometry>
      <material
        name="">
        <color
          rgba="0.79216 0.81961 0.93333 1" />
      </material>
    </visual>
    <collision>
      <origin
        xyz="0 0 0"
        rpy="0 0 0" />
      <geometry>
        <mesh
          filename="package://busbot/meshes/br_axle_link.STL" />
      </geometry>
    </collision>
  </link>
  <joint
    name="br_axle_joint"
    type="fixed">
    <origin
      xyz="-0.42815 -0.20136 -0.035521"
      rpy="3.1416 0 -1.5708" />
    <parent
      link="base_link" />
    <child
      link="br_axle_link" />
    <axis
      xyz="0 0 0" />
  </joint>
  <link
    name="br_wheel_link">
    <inertial>
      <origin
        xyz="0 0 -0.065272"
        rpy="0 0 0" />
      <mass
        value="3" />
      <inertia
        ixx="0.065282"
        ixy="0"
        ixz="1.0503E-19"
        iyy="0.065282"
        iyz="4.6168E-20"
        izz="0.10708" />
    </inertial>
    <visual>
      <origin
        xyz="0 0 0"
        rpy="0 0 0" />
      <geometry>
        <mesh
          filename="package://busbot/meshes/br_wheel_link.STL" />
      </geometry>
      <material
        name="">
        <color
          rgba="0.79608 0.82353 0.93725 1" />
      </material>
    </visual>
    <collision>
      <origin
        xyz="0 0 0"
        rpy="0 0 0" />
      <geometry>
        <mesh
          filename="package://busbot/meshes/br_wheel_link.STL" />
      </geometry>
    </collision>
  </link>
  <joint
    name="br_wheel_joint"
    type="continuous">
    <origin
      xyz="0.0787399999999999 0 0.3429"
      rpy="1.5707963267949 0.431002781851365 -1.5707963267949" />
    <parent
      link="br_axle_link" />
    <child
      link="br_wheel_link" />
    <axis
      xyz="0 0 -1" />
    <limit
      effort="100"
      velocity="1000" />
  </joint>
  <link
    name="man_base_link">
    <inertial>
      <origin
        xyz="0.33385 -0.023562 0.42168"
        rpy="-1.5708 0 -1.5708" />
      <mass
        value="1" />
      <inertia
        ixx="0.20413"
        ixy="3.2162E-18"
        ixz="-3.544E-11"
        iyy="0.015893"
        iyz="2.2005E-16"
        izz="0.21084" />
    </inertial>
    <visual>
      <origin
        xyz="0 0 0"
        rpy="0 0 0" />
      <geometry>
        <mesh
          filename="package://busbot/meshes/man_base_link.STL" />
      </geometry>
      <material
        name="">
        <color
          rgba="1 1 1 1" />
      </material>
    </visual>
    <collision>
      <origin
        xyz="0 0 0"
        rpy="0 0 0" />
      <geometry>
        <mesh
          filename="package://busbot/meshes/man_base_link.STL" />
      </geometry>
    </collision>
  </link>
  <joint
    name="man_base_joint"
    type="fixed">
    <origin
      xyz="0.33385 -0.023562 0.42168"
      rpy="-1.5708 0 -1.5708" />
    <parent
      link="base_link" />
    <child
      link="man_base_link" />
    <axis
      xyz="0 0 0" />
  </joint>
  <link
    name="link_1">
    <inertial>
      <origin
        xyz="-1.7347E-17 -0.31055 3.3307E-16"
        rpy="0 0 0" />
      <mass
        value="1" />
      <inertia
        ixx="0.20413"
        ixy="3.2162E-18"
        ixz="-3.544E-11"
        iyy="0.015893"
        iyz="2.2005E-16"
        izz="0.21084" />
    </inertial>
    <visual>
      <origin
        xyz="0 0 0"
        rpy="0 0 0" />
      <geometry>
        <mesh
          filename="package://busbot/meshes/link_1.STL" />
      </geometry>
      <material
        name="">
        <color
          rgba="0.79216 0.81961 0.93333 1" />
      </material>
    </visual>
    <collision>
      <origin
        xyz="0 0 0"
        rpy="0 0 0" />
      <geometry>
        <mesh
          filename="package://busbot/meshes/link_1.STL" />
      </geometry>
    </collision>
  </link>
  <joint
    name="joint_0"
    type="revolute">
    <origin
      xyz="0 -0.0761999999999999 0"
      rpy="0 0 0" />
    <parent
      link="man_base_link" />
    <child
      link="link_1" />
    <axis
      xyz="0 -1 0" />
    <limit
      lower="-3.14"
      upper="3.14"
      effort="100"
      velocity="1000" />
  </joint>
  <link
    name="link_2">
    <inertial>
      <origin
        xyz="-3.0878E-16 -0.31189 -2.2204E-16"
        rpy="0 0 0" />
      <mass
        value="0.75" />
      <inertia
        ixx="0.20212"
        ixy="-1.6857E-16"
        ixz="-3.544E-11"
        iyy="0.015851"
        iyz="-4.4604E-18"
        izz="0.20878" />
    </inertial>
    <visual>
      <origin
        xyz="0 0 0"
        rpy="0 0 0" />
      <geometry>
        <mesh
          filename="package://busbot/meshes/link_2.STL" />
      </geometry>
      <material
        name="">
        <color
          rgba="0.79216 0.81961 0.93333 1" />
      </material>
    </visual>
    <collision>
      <origin
        xyz="0 0 0"
        rpy="0 0 0" />
      <geometry>
        <mesh
          filename="package://busbot/meshes/link_2.STL" />
      </geometry>
    </collision>
  </link>
  <joint
    name="joint_1"
    type="revolute">
    <origin
      xyz="0 -0.5842 -0.0508"
      rpy="-1.5708 0 0" />
    <parent
      link="link_1" />
    <child
      link="link_2" />
    <axis
      xyz="-1 0 0" />
    <limit
      lower="-3.14"
      upper="3.14"
      effort="100"
      velocity="1000" />
  </joint>
  <link
    name="link_3">
    <inertial>
      <origin
        xyz="-2.6021E-16 -0.25686 0"
        rpy="0 0 0" />
      <mass
        value="0.5" />
      <inertia
        ixx="0.11454"
        ixy="-1.0394E-16"
        ixz="-2.647E-19"
        iyy="0.0086553"
        iyz="-3.6404E-18"
        izz="0.1145" />
    </inertial>
    <visual>
      <origin
        xyz="0 0 0"
        rpy="0 0 0" />
      <geometry>
        <mesh
          filename="package://busbot/meshes/link_3.STL" />
      </geometry>
      <material
        name="">
        <color
          rgba="0.79216 0.81961 0.93333 1" />
      </material>
    </visual>
    <collision>
      <origin
        xyz="0 0 0"
        rpy="0 0 0" />
      <geometry>
        <mesh
          filename="package://busbot/meshes/link_3.STL" />
      </geometry>
    </collision>
  </link>
  <joint
    name="joint_2"
    type ="revolute">
    <origin
      xyz="0 -0.5334 0"
      rpy="0 0 0" />
    <parent
      link="link_2" />
    <child
      link="link_3" />
    <axis
      xyz="-1 0 0" />
    <limit
      lower="-3.14"
      upper="3.14"
      effort="100"
      velocity="1000" />
  </joint>
  <link
    name="link_4">
    <inertial>
      <origin
        xyz="-2.4286E-17 0.06332 0"
        rpy="0 0 0" />
      <mass
        value="0.25" />
      <inertia
        ixx="0.0027129"
        ixy="1.4485E-19"
        ixz="7.7428E-20"
        iyy="0.0021556"
        iyz="-1.1919E-19"
        izz="0.0027" />
    </inertial>
    <visual>
      <origin
        xyz="0 0 0"
        rpy="0 0 0" />
      <geometry>
        <mesh
          filename="package://busbot/meshes/link_4.STL" />
      </geometry>
      <material
        name="">
        <color
          rgba="0.79216 0.81961 0.93333 1" />
      </material>
    </visual>
    <collision>
      <origin
        xyz="0 0 0"
        rpy="0 0 0" />
      <geometry>
        <mesh
          filename="package://busbot/meshes/link_4.STL" />
      </geometry>
    </collision>
  </link>
  <joint
    name="joint_3"
    type="revolute">
    <origin
      xyz="0 -0.508 0"
      rpy="0 0 3.14159265358979" />
    <parent
      link="link_3" />
    <child
      link="link_4" />
    <axis
      xyz="0 1 0" />
    <limit
      lower="-3.14"
      upper="3.14"
      effort="100"
      velocity="1000" />
  </joint>
  <!-- <link
    name="grip_right">
    <inertial>
      <origin
        xyz="-0.0078438 0.031706 0"
        rpy="0 0 0" />
      <mass
        value="0.042967" />
      <inertia
        ixx="2.0273E-05"
        ixy="-9.2175E-07"
        ixz="-4.0035E-21"
        iyy="4.5283E-06"
        iyz="-1.9183E-20"
        izz="2.0228E-05" />
    </inertial>
    <visual>
      <origin
        xyz="0 0 0"
        rpy="0 0 0" />
      <geometry>
        <mesh
          filename="package://busbot/meshes/grip_right.STL" />
      </geometry>
      <material
        name="">
        <color
          rgba="0.79216 0.81961 0.93333 1" />
      </material>
    </visual>
    <collision>
      <origin
        xyz="0 0 0"
        rpy="0 0 0" />
      <geometry>
        <mesh
          filename="package://busbot/meshes/grip_right.STL" />
      </geometry>
    </collision>
  </link>
  <joint
    name="gr_joint"
    type="prismatic">
    <origin
      xyz="-0.00380999999999991 0.127 0"
      rpy="0 0 0" />
    <parent
      link="link_4" />
    <child
      link="grip_right" />
    <axis
      xyz="-1 0 0" />
    <limit
      lower="10"
      upper="10"
      effort="100"
      velocity="1000" />
  </joint>
  <link
    name="grip_left">
    <inertial>
      <origin
        xyz="-0.0054638 -0.031706 -4.4409E-16"
        rpy="0 0 0" />
      <mass
        value="0.042967" />
      <inertia
        ixx="2.0273E-05"
        ixy="9.2175E-07"
        ixz="-3.9431E-21"
        iyy="4.5283E-06"
        iyz="1.7641E-20"
        izz="2.0228E-05" />
    </inertial>
    <visual>
      <origin
        xyz="0 0 0"
        rpy="0 0 0" />
      <geometry>
        <mesh
          filename="package://busbot/meshes/grip_left.STL" />
      </geometry>
      <material
        name="">
        <color
          rgba="0.79216 0.81961 0.93333 1" />
      </material>
    </visual>
    <collision>
      <origin
        xyz="0 0 0"
        rpy="0 0 0" />
      <geometry>
        <mesh
          filename="package://busbot/meshes/grip_left.STL" />
      </geometry>
    </collision>
  </link>
  <joint
    name="gl_joint"
    type="prismatic">
    <origin
      xyz="0.00619000000000009 0.127 0"
      rpy="0 0 3.14159265358979" />
    <parent
      link="link_4" />
    <child
      link="grip_left" />
    <axis
      xyz="1 0 0" />
    <limit
      lower="10"
      upper="10"
      effort="100"
      velocity="1000" />
  </joint> -->

  <ros2_control name="GazeboSystem" type="system">
    <hardware>
        <plugin>gazebo_ros2_control/GazeboSystem</plugin>
    </hardware>
  # Velocity Controllers

  <joint name="br_wheel_joint">
      <command_interface name="velocity">
          <param name="min">-1000.0</param>
          <param name="max">1000.0</param>
      </command_interface>
      <state_interface name="position"/>
      <state_interface name="velocity"/>
  </joint>

  <joint name="bl_wheel_joint">
      <command_interface name="velocity">
          <param name="min">-1000.0</param>
          <param name="max">1000.0</param>
      </command_interface>
      <state_interface name="position"/>
      <state_interface name="velocity"/>
  </joint>

  <joint name="fl_wheel_joint">
      <command_interface name="velocity">
          <param name="min">-1000.0</param>
          <param name="max">1000.0</param>
      </command_interface>
      <state_interface name="position"/>
      <state_interface name="velocity"/>
  </joint>

  <joint name="fr_wheel_joint">
      <command_interface name="velocity">
          <param name="min">-1000.0</param>
          <param name="max">1000.0</param>
      </command_interface>
      <state_interface name="position"/>
      <state_interface name="velocity"/>
  </joint>

  # Position Controller
  <joint name="fl_axle_joint">
      <command_interface name="position">
          <param name="min">-3.14</param>
          <param name="max">3.14</param>
      </command_interface>
      <state_interface name="position"/>
      <state_interface name="velocity"/>
  </joint>

  <joint name="fl_axle_joint">
      <command_interface name="velocity">
          <param name="min">-3.14</param>
          <param name="max">3.14</param>
      </command_interface>
      <state_interface name="position"/>
      <state_interface name="velocity"/>
  </joint>

  <joint name="fr_axle_joint">
      <command_interface name="position">
          <param name="min">-3.14</param>
          <param name="max">3.14</param>
      </command_interface>
      <state_interface name="position"/>
      <state_interface name="velocity"/>
  </joint>

  <joint name="fr_axle_joint">
      <command_interface name="velocity">
          <param name="min">-3.14</param>
          <param name="max">3.14</param>
      </command_interface>
      <state_interface name="position"/>
      <state_interface name="velocity"/>
  </joint>

  <joint name="joint_0">
      <command_interface name="position">
          <param name="min">-3.14</param>
          <param name="max">3.14</param>
      </command_interface>
      <state_interface name="position"/>
      <state_interface name="velocity"/>
  </joint>

  <joint name="joint_0">
      <command_interface name="velocity">
          <param name="min">-3.14</param>
          <param name="max">3.14</param>
      </command_interface>
      <state_interface name="position"/>
      <state_interface name="velocity"/>
  </joint>

  <joint name="joint_1">
      <command_interface name="position">
          <param name="min">-3.14</param>
          <param name="max">3.14</param>
      </command_interface>
      <state_interface name="position"/>
      <state_interface name="velocity"/>
  </joint>

  <joint name="joint_1">
      <command_interface name="velocity">
          <param name="min">-3.14</param>
          <param name="max">3.14</param>
      </command_interface>
      <state_interface name="position"/>
      <state_interface name="velocity"/>
  </joint>

  <joint name="joint_2">
      <command_interface name="position">
          <param name="min">-3.14</param>
          <param name="max">3.14</param>
      </command_interface>
      <state_interface name="position"/>
      <state_interface name="velocity"/>
  </joint>

  <joint name="joint_2">
      <command_interface name="velocity">
          <param name="min">-3.14</param>
          <param name="max">3.14</param>
      </command_interface>
      <state_interface name="position"/>
      <state_interface name="velocity"/>
  </joint>

  <joint name="joint_3">
      <command_interface name="position">
          <param name="min">-3.14</param>
          <param name="max">3.14</param>
      </command_interface>
      <state_interface name="position"/>
      <state_interface name="velocity"/>
  </joint>

  <joint name="joint_3">
      <command_interface name="velocity">
          <param name="min">-3.14</param>
          <param name="max">3.14</param>
      </command_interface>
      <state_interface name="position"/>
      <state_interface name="velocity"/>
  </joint>

  <!-- <joint name="gl_joint">
      <command_interface name="position">
          <param name="min">-3.14</param>
          <param name="max">3.14</param>
      </command_interface>
      <state_interface name="position"/>
      <state_interface name="velocity"/>
  </joint>

  <joint name="gl_joint">
      <command_interface name="velocity">
          <param name="min">-3.14</param>
          <param name="max">3.14</param>
      </command_interface>
      <state_interface name="position"/>
      <state_interface name="velocity"/>
  </joint>

  <joint name="gr_joint">
      <command_interface name="position">
          <param name="min">-3.14</param>
          <param name="max">3.14</param>
      </command_interface>
      <state_interface name="position"/>
      <state_interface name="velocity"/>
  </joint>

  <joint name="gr_joint">
      <command_interface name="velocity">
          <param name="min">-3.14</param>
          <param name="max">3.14</param>
      </command_interface>
      <state_interface name="position"/>
      <state_interface name="velocity"/>
  </joint> -->

  </ros2_control>

  <gazebo>
    <plugin filename="libgazebo_ros2_control.so" name="gazebo_ros2_control">
        <parameters>$(find busbot)/config/control.yaml</parameters>
    </plugin>
  </gazebo>

  <gazebo reference="fr_wheel_link">
      <xacro:wheel_color />
  </gazebo>

  <gazebo reference="br_wheel_link">
      <xacro:wheel_color />
  </gazebo>

  <gazebo reference="fl_wheel_link">
      <xacro:wheel_color />
  </gazebo>

  <gazebo reference="bl_wheel_link"> 
      <xacro:wheel_color />
  </gazebo>

  <gazebo reference="base_link">
    <gravity>true</gravity>
    <sensor name="imu_sensor" type="imu">
      <always_on>true</always_on>
      <update_rate>100</update_rate>
      <visualize>true</visualize>
      <topic>__default_topic__</topic>
      <plugin filename="libgazebo_ros_imu_sensor.so" name="imu_plugin">
        <topicName>imu</topicName>
        <bodyName>base_link</bodyName>
        <updateRateHZ>10.0</updateRateHZ>
        <gaussianNoise>0.0</gaussianNoise>
        <xyzOffset>0 0 0</xyzOffset>
        <rpyOffset>0 0 0</rpyOffset>
        <frameName>base_link</frameName>
        <initialOrientationAsReference>false</initialOrientationAsReference>
      </plugin>
      <pose>0 0 0 0 0 0</pose>
    </sensor>
  </gazebo>

  <gazebo>
    <plugin name='vacuum_gripper' filename='libgazebo_ros_vacuum_gripper.so'>

      <!-- This part can be commented out if not required -->
      <ros>

        <!-- Add a namespace -->

        <namespace>/busbot</namespace>

        <!-- Remapping service and topic names -->
        <remapping>switch:=custom_switch</remapping>
        <remapping>grasping:=custom_grasping</remapping>
      </ros>

      <!-- Link associated with gripper -->
      <link_name>link_4</link_name>

      <!-- Max distance to attract entities -->
      <max_distance>0.4</max_distance>

      <!-- List of entities to be not attracted by the gripper -->
      <fixed>ground_plane</fixed>
      <fixed>wall</fixed>

    </plugin>
  </gazebo>

</robot>